Workbook

Sheet Prospection 100 Crèches
A1: 🌳 PROSPECTION PETIT BAOBAB — 100 CRÈCHES · OUAGADOUGOU · Mis à jour Juillet 2026
A2: ID | B2: Nom École / Crèche | C2: Quartier / Localisation précise | D2: Arrondissement | E2: Type | F2: Nb Élèves | G2: Priorité | H2: Nom Directeur/trice | I2: Tél 1 (Dir/WhatsApp) | J2: Tél 2 (Secrétariat) | K2: Email / Réseaux | L2: STATUT | M2: Date 1er Contact | N2: Méthode Contact | O2: Notes & Approche | P2: Date RDV Démo | Q2: Prof Référent | R2: Retour Démo | S2: Objection | T2: Prochaine Action | U2: Commentaire Final
A3: 001 | B3: Sheri Kidz Cottage Crèche-Maternelle | C3: Cité Azimmo, Ouaga 2000 | D3: Boulmiougou | E3: Privé · Crèche/Maternelle/Primaire | F3: 150 | G3: A | H3: À identifier | I3: 61 37 92 55 | K3: FB: Sherikidz | L3: À contacter | N3: Porte à porte | O3: ✅ Confirmée. Source FB/annuaire. Complexe complet. Zone premium Azimmo. | T3: Visiter sem.1
A4: 002 | B4: Rayan Garden | C4: 388 Cité Azimmo, Secteur 16 | D4: Boulmiougou | E4: Privé · Crèche/Maternelle | F4: 60 | G4: A | H4: À identifier | I4: 77 94 73 63 | J4: 72 09 01 23 | L4: À contacter | N4: Porte à porte | O4: ✅ Confirmée. Source annuaire. Même tournée que Sheri Kidz. Appeler d'abord. | T4: Appeler sem.1
A5: 003 | B5: Crèche privée La Colombe | C5: Sect.16 Cité Azimmo Ouaga 2000, Villa 92 | D5: Boulmiougou | E5: Privé · Crèche | F5: 50 | G5: A | H5: À identifier | I5: 78 55 59 55 | L5: À contacter | N5: Appel d'abord | O5: ✅ Confirmée. Source expat.com. Adresse précise villa 92 Azimmo. | T5: Appeler sem.1
A6: 004 | B6: Les Chérubins Ouaga | C6: Ouaga 2000, côté sud Joly Hotel, 50m Rosa Deventi | D6: Boulmiougou | E6: Privé · Crèche/Maternelle/Primaire Bilingue | F6: 120 | G6: A | H6: À identifier | I6: 25 37 44 08 | J6: 58 63 21 63 | K6: 63 29 40 29 · FB: Les Chérubins | L6: À contacter | N6: Appel d'abord | O6: ✅ Confirmée. Source Facebook + SchoolListings. Bilingue. 3 mois à CM2. Salle climatisée. Camp vacances. | T6: Appeler sem.1
A7: 005 | B7: Le Château des Petits Anges | C7: Ouagadougou | D7: Centre | E7: Privé · Crèche/Maternelle | F7: 90 | G7: A | H7: À identifier | K7: lechateaudespetitsanges.com | L7: À contacter | N7: Site web | O7: ✅ Site web actif. Position premium. À demander contacts sur le site. | T7: Visiter sem.1
A8: 006 | B8: Les Lucioles — Crèche Halte-garderie | C8: Ouagadougou | D8: Centre | E8: Privé · Crèche/Halte-garderie | F8: 70 | G8: A | H8: À identifier | I8: 72 74 00 00 | L8: À contacter | N8: Appel d'abord | O8: ✅ Confirmée. Source expat.com. Halte-garderie = parents actifs mobiles. | T8: Appeler sem.1
A9: 007 | B9: Crèche-Maternelle Les Élus | C9: BP255 Ouagadougou 11 | D9: Centre | E9: Privé · Crèche/Maternelle | F9: 80 | G9: A | H9: Mme Ouedraogo Zalissa | I9: 70 24 93 39 | J9: 50 46 23 01 | L9: À contacter | N9: Appel d'abord | O9: ✅ Confirmée. Source expat.com. Directrice Zalissa identifiée. Contact direct possible. | T9: Appeler sem.1
A10: 008 | B10: Blossom Crèche et Maternelle | C10: Ouagadougou | D10: Centre | E10: Privé · Crèche/Maternelle | F10: 85 | G10: A | H10: À identifier | K10: blossom-burkina.com | L10: À contacter | N10: Site web | O10: ✅ Site web actif blossom-burkina.com. Moderne et sécurisé selon présentation. Cible digitale. | T10: Contacter via site sem.1
A11: 009 | B11: Crèche et Maternelle privée Eden | C11: Saaba (périphérie Est) | D11: Saaba | E11: Privé · Crèche/Maternelle | F11: 75 | G11: B | H11: Ouedraogo S Haoula | I11: 62 29 29 29 | J11: 50 40 70 10 | L11: À contacter | N11: Appel d'abord | O11: ✅ Confirmée. Directrice Haoula identifiée. Source expat.com. Tournée périphérie Est. | T11: Appeler sem.2
A12: 010 | B12: Notre-Dame de la Paix de Saaba | C12: Saaba | D12: Saaba | E12: Privé · Crèche/Maternelle Bilingue | F12: 70 | G12: B | H12: À identifier | L12: À contacter | N12: Porte à porte | O12: ✅ Confirmée. Source search 2024. Bilingue. Saaba résidentiel. | T12: Terrain sem.2
A13: 011 | B13: Garderie Kiswendsida | C13: Ouagadougou Centre (GPS: 8GCG+JQ9) | D13: Centre | E13: Privé · Garderie | F13: 45 | G13: B | H13: À identifier | I13: 63 00 40 66 | K13: GoAfricaOnline | L13: À contacter | N13: Appel d'abord | O13: ✅ Confirmée. Source GoAfricaOnline. Coordonnées GPS disponibles. | T13: Appeler sem.2
A14: 012 | B14: International Trilingual School | C14: 08 BP11461, Ouaga 2000 | D14: Boulmiougou | E14: Privé · International Trilingue | F14: 120 | G14: A | H14: À identifier | I14: 07 20 44 44 | L14: À contacter | N14: Appel d'abord | O14: ✅ Confirmée. Source GoAfricaOnline. 3 langues = parents très aisés. Budget élevé. | T14: Appeler sem.1
A15: 013 | B15: Complex School Universalis | C15: BP2078, Ouagadougou | D15: Centre | E15: Privé · Maternelle/Primaire | F15: 150 | G15: B | H15: À identifier | I15: 25 38 25 14 | K15: GoAfricaOnline | L15: À contacter | N15: Appel d'abord | O15: ✅ Confirmée. Source GoAfricaOnline. Complexe multi-cycles. | T15: Appeler sem.2
A16: 014 | B16: Marvynn's School | C16: Ouagadougou | D16: Centre | E16: Privé · Maternelle | F16: 70 | G16: B | H16: À identifier | I16: 05 10 10 10 | K16: GoAfricaOnline | L16: À contacter | N16: Appel d'abord | O16: ✅ Confirmée. Source GoAfricaOnline. Numéro mémorable. | T16: Appeler sem.2
A17: 015 | B17: Nursery Les Champions | C17: Koulouba, BP 64 37 | D17: Baskuy | E17: Privé · Nursery/Crèche | F17: 50 | G17: B | H17: À identifier | I17: 63 49 58 40 | K17: GoAfricaOnline | L17: À contacter | N17: Porte à porte | O17: ✅ Confirmée. Source GoAfricaOnline. Zone diplomatique Koulouba. | T17: Terrain sem.2
A18: 016 | B18: SATARA International School | C18: BP2837, Ouagadougou | D18: Centre | E18: Privé · International | F18: 100 | G18: A | H18: À identifier | I18: 25 30 25 18 | K18: GoAfricaOnline | L18: À contacter | N18: Appel d'abord | O18: ✅ Confirmée. Source GoAfricaOnline. Internationale = budget premium. | T18: Appeler sem.1
A19: 017 | B19: Mother Franco-Arabe Petit Musulman | C19: Paglayiri, Secteur 25 | D19: Nongremassom | E19: Communautaire · Crèche Franco-Arabe | F19: 55 | G19: C | H19: À identifier | I19: 25 65 67 79 | K19: GoAfricaOnline | L19: À contacter | N19: Porte à porte | O19: ✅ Confirmée. Source GoAfricaOnline. Communauté franco-arabe. Approche culturelle spécifique. | T19: Terrain sem.3
A20: 018 | B20: Ma Basyiire (Mères sans soucis) | C20: Marché Kaatr-Yaar, Secteur 28 | D20: Bogodogo | E20: Communautaire/ONG · Crèche | F20: 100 | G20: C | H20: À identifier | K20: sosenfants.info | L20: À contacter | N20: Porte à porte | O20: ✅ Confirmée. Source SOS Enfants. ONG accueille 100 enfants 3 mois-3 ans. Tarif social. | T20: Terrain sem.3
A21: 019 | B21: Groupe Scolaire des Semailles | C21: Gounghin-Kaizer | D21: Baskuy | E21: Privé · Maternelle/Primaire | F21: 220 | G21: B | H21: À identifier | I21: 70 24 43 75 | L21: À contacter | N21: Appel d'abord | O21: ✅ Confirmée. Source annuaire. Multi-cycles = plan École-Pro annuel plus pertinent. | T21: Appeler sem.2
A22: 020 | B22: Les Angelots du Faso (Siège) | C22: Gounghin, En face Centre Prof. Yennega | D22: Baskuy | E22: Privé · Crèche/Maternelle Bilingue | F22: 90 | G22: A | H22: À identifier | I22: 25 40 89 59 | K22: FB: Les Angelots du Faso | L22: À contacter | N22: Appel d'abord | O22: ✅ Confirmée. Source Kinamap + search. Annexe aussi Cité SOCOGIB face 75e anniversaire. | T22: Appeler sem.1
A23: 021 | B23: Les Angelots du Faso (Annexe) | C23: Cité SOCOGIB, face 75ème Anniversaire | D23: Baskuy | E23: Privé · Crèche/Maternelle Bilingue | F23: 60 | G23: A | H23: À identifier | I23: 25 40 89 59 | K23: FB: Les Angelots du Faso | L23: À contacter | N23: Porte à porte | O23: ✅ Confirmée (annexe du 020). Même groupe. Contacter siège d'abord. | T23: Terrain sem.2
A24: 022 | B24: Ashraf Garden Crèche et Maternelle | C24: Koulouba, face Ministère Affaires Étrangères | D24: Baskuy | E24: Privé · Crèche/Maternelle | F24: 65 | G24: A | H24: À identifier | K24: FB: Ashraf Garden | L24: À contacter | N24: Porte à porte | O24: ✅ Confirmée. Source search 2024. Zone diplomatique. 3 mois à 5 ans. Cadre sécurisé. | T24: Terrain sem.1
A25: 023 | B25: Crèche Maternelle Saint Ange K | C25: Nioko 1 Barogo, non loin Complexe Wend Raabo | D25: Nongremassom | E25: Privé · Crèche/Maternelle | F25: 55 | G25: C | H25: À identifier | L25: À contacter | N25: Terrain | O25: ✅ Confirmée. Source search 2024. Périphérie nord. Tournée dédiée. | T25: Terrain sem.4
A26: 024 | B26: La Petite Académie Tous Unis | C26: Sect.35 Nonghin, voie princ. Cité Rimkieta | D26: Nongremassom | E26: Privé · Crèche/Maternelle Bilingue | F26: 70 | G26: C | H26: À identifier | K26: FB: La Petite Académie | L26: À contacter | N26: Terrain | O26: ✅ Confirmée. Source search 2024. Bilingue. Zone Rimkieta en croissance. | T26: Terrain sem.4
A27: 025 | B27: Complexe Scolaire Deo Gratias | C27: Sandogo, Ouagadougou (GPS: 8C6W+VV5) | D27: Bogodogo | E27: Privé · Complexe | F27: 120 | G27: C | H27: À identifier | L27: À contacter | N27: Terrain | O27: ✅ Confirmée. Source search 2024. Coordonnées GPS. Éveil cognitif, psychomoteur, artistique. | T27: Terrain sem.3
A28: 026 | B28: Crèche BILINGUE Amour, Tendresse & Câlin | C28: Ouagadougou | D28: Centre | E28: Privé · Crèche/Maternelle Bilingue | F28: 60 | G28: B | H28: À identifier | K28: ayeler.com | L28: À contacter | N28: Appel d'abord | O28: ✅ Confirmée. Source ayeler.com. Bilingue. Cadre paisible. Contacter via Ayeler. | T28: Terrain sem.2
A29: 027 | B29: Crèche Maternelle la Grâce Divine Internationale | C29: Ouagadougou | D29: Centre | E29: Privé · Crèche/Maternelle Internationale | F29: 80 | G29: B | H29: À identifier | L29: À contacter | N29: Terrain | O29: ✅ Confirmée. Source SchoolListings. 'Internationale' dans le nom = clientèle aisée. | T29: Terrain sem.2
A30: 028 | B30: Complexe Scolaire Privé Anika | C30: Ouagadougou | D30: Centre | E30: Privé · Complexe Scolaire | F30: 160 | G30: B | H30: À identifier | L30: À contacter | N30: Terrain | O30: Source SchoolListings. Complexe complet. Contacter pour confirmer cycle préscolaire. | T30: Terrain sem.2
A31: 029 | B31: École Maternelle et Primaire Acajou | C31: Ouagadougou | D31: Centre | E31: Privé · Maternelle/Primaire | F31: 100 | G31: B | H31: À identifier | L31: À contacter | N31: Terrain | O31: Source SchoolListings. Nom original. À confirmer existence cycle crèche. | T31: Terrain sem.2
A32: 030 | B32: École Maternelle Le Petit David | C32: Rue 19.33, Ouagadougou | D32: Baskuy | E32: Privé · Maternelle | F32: 65 | G32: B | H32: À identifier | L32: À contacter | N32: Terrain | O32: Source SchoolListings. Adresse rue connue. À confirmer terrain. | T32: Terrain sem.2
A33: 031 | B33: École Maternelle Primaire Privée Nambita | C33: Ouagadougou | D33: Centre | E33: Privé · Maternelle/Primaire | F33: 90 | G33: B | H33: À identifier | L33: À contacter | N33: Terrain | O33: Source SchoolListings. À confirmer. | T33: Terrain sem.3
A34: 032 | B34: Complexe Scolaire La Réussite | C34: Zogona, Secteur 14 | D34: Baskuy | E34: Privé · Complexe Scolaire | F34: 200 | G34: A | H34: À identifier | L34: À contacter | N34: Porte à porte | O34: Zogona = quartier université. Parents enseignants/fonctionnaires. À identifier directeur. | T34: Terrain sem.2
A35: 033 | B35: École Maternelle La Cigogne | C35: Hamdalaye, Secteur 8 | D35: Baskuy | E35: Privé · Maternelle | F35: 85 | G35: B | H35: À identifier | L35: À contacter | N35: Porte à porte | O35: Hamdalaye = quartier dense résidentiel. À confirmer. | T35: Terrain sem.2
A36: 034 | B36: Crèche Les Colibris | C36: Paspanga | D36: Baskuy | E36: Privé · Crèche/Maternelle | F36: 65 | G36: B | H36: À identifier | L36: À contacter | N36: Porte à porte | O36: Paspanga résidentiel. À confirmer terrain. | T36: Terrain sem.2
A37: 035 | B37: Jardin d'Enfants Mon Soleil | C37: Dapoya | D37: Baskuy | E37: Privé · Maternelle | F37: 70 | G37: B | H37: À identifier | L37: À contacter | N37: Porte à porte | O37: Centre-ville Dapoya. Quartier mixte. À confirmer. | T37: Terrain sem.2
A38: 036 | B38: Crèche Les Marguerites | C38: Zone du Bois / 1200 Logements | D38: Baskuy | E38: Privé · Crèche | F38: 60 | G38: B | H38: À identifier | L38: À contacter | N38: Porte à porte | O38: Zone 1200 logements = fonctionnaires. Cible B. À confirmer. | T38: Terrain sem.3
A39: 037 | B39: École Préscolaire La Source | C39: Larlé | D39: Baskuy | E39: Privé · Maternelle | F39: 90 | G39: B | H39: À identifier | L39: À contacter | N39: Porte à porte | O39: Larlé en face Marché du 10. Quartier dense. À confirmer. | T39: Terrain sem.3
A40: 038 | B40: Crèche Sainte-Thérèse | C40: Secteur 4, Kamsonghin | D40: Baskuy | E40: Privé cath. · Crèche | F40: 65 | G40: B | H40: À identifier | L40: À contacter | N40: Porte à porte | O40: Réseau catholique diocèse Ouaga. À confirmer adresse exacte. | T40: Terrain sem.3
...

Sheet Tableau de bord
A1: 📊 TABLEAU DE BORD — 100 Crèches · Petit Baobab Ouagadougou
A2: Auto-calculé en temps réel depuis la feuille Prospection
A4: Statut | B4: Nombre | C4: % Pipeline | D4: Priorité | E4: Nombre
A5: À contacter | B5: =COUNTIF('Prospection 100 Crèches'!L:L,"À contacter") -> 100 | C5: =IFERROR(B5/100,"—") -> 1 | D5: Priorité A | E5: =COUNTIF('Prospection 100 Crèches'!G:G,"A") -> 27
A6: RDV pris | B6: =COUNTIF('Prospection 100 Crèches'!L:L,"RDV pris") -> 0 | C6: =IFERROR(B6/100,"—") -> 0 | D6: Priorité B | E6: =COUNTIF('Prospection 100 Crèches'!G:G,"B") -> 49
A7: Démo faite | B7: =COUNTIF('Prospection 100 Crèches'!L:L,"Démo faite") -> 0 | C7: =IFERROR(B7/100,"—") -> 0 | D7: Priorité C | E7: =COUNTIF('Prospection 100 Crèches'!G:G,"C") -> 24
A8: Pilote en cours | B8: =COUNTIF('Prospection 100 Crèches'!L:L,"Pilote en cours") -> 0 | C8: =IFERROR(B8/100,"—") -> 0
A9: Gagné | B9: =COUNTIF('Prospection 100 Crèches'!L:L,"Gagné") -> 0 | C9: =IFERROR(B9/100,"—") -> 0 | D9: Arrondissement | E9: Nb Cibles
A10: Perdu | B10: =COUNTIF('Prospection 100 Crèches'!L:L,"Perdu") -> 0 | C10: =IFERROR(B10/100,"—") -> 0 | D10: Baskuy | E10: =COUNTIF('Prospection 100 Crèches'!D:D,"*Baskuy*") -> 36
A11: TOTAL CIBLES | B11: =COUNTA('Prospection 100 Crèches'!L3:L102) -> 100 | D11: Boulmiougou | E11: =COUNTIF('Prospection 100 Crèches'!D:D,"*Boulmiougou*") -> 13
D12: Bogodogo | E12: =COUNTIF('Prospection 100 Crèches'!D:D,"*Bogodogo*") -> 9
D13: Nongremassom | E13: =COUNTIF('Prospection 100 Crèches'!D:D,"*Nongremassom*") -> 18
D14: Sig-Nonghin | E14: =COUNTIF('Prospection 100 Crèches'!D:D,"*Sig-Nonghin*") -> 4
D15: Saaba | E15: =COUNTIF('Prospection 100 Crèches'!D:D,"*Saaba*") -> 3
A18: INDICATEURS CLÉS
A19: Taux conversion (Gagné/100 cibles) | C19: =IFERROR(COUNTIF('Prospection 100 Crèches'!L:L,"Gagné")/100,"0%") -> 0
A20: En cours actif (RDV+Démo+Pilote) | C20: =COUNTIF('Prospection 100 Crèches'!L:L,"RDV pris")+COUNTIF('Prospection 100 Crèches'!L:L,"Démo faite")+COUNTIF('Prospection 100 Crèches'!L:L,"Pilote en cours") -> 0
A21: Sans Prochaine Action (⚠️) | C21: =COUNTBLANK('Prospection 100 Crèches'!T3:T102) -> 0
A22: Pilotes en cours | C22: =COUNTIF('Prospection 100 Crèches'!L:L,"Pilote en cours") -> 0
A23: Contacts confirmés (✅ notes) | C23: =COUNTIF('Prospection 100 Crèches'!O:O,"✅*") -> 39

Sheet Légende & Terrain
A1: 📋 LÉGENDE · RÈGLES D'OR · GUIDE TERRAIN
A3: CODE COULEUR STATUT
A4: À contacter | B4: ◀ | C4: Dans la liste — pas encore contacté
A5: RDV pris | B5: ◀ | C5: Chaud — RDV confirmé à venir
A6: Démo faite | B6: ◀ | C6: Très chaud — démo réalisée
A7: Pilote en cours | B7: ◀ | C7: Accès gratuit 30j en cours
A8: Gagné | B8: ◀ | C8: 🎉 École payante — succès !
A9: Perdu | B9: ◀ | C9: Fermé pour l'instant
A12: 5 RÈGLES D'OR
A13: Règle des 24h | B13: ⏰ | C13: Notes + Prochaine Action le soir même après chaque visite. Sinon c'est perdu.
A14: Règle col. T | B14: 📅 | C14: Aucune crèche sans Prochaine Action. Même 'Relancer dans 1 mois'.
A15: Règle du Quartier | B15: 🗺 | C15: Filtrer par arrondissement. 5 crèches dans une zone = 3h de zém économisées.
A16: Règle du Prénom | B16: 👤 | C16: Toujours noter le prénom de la directrice. L'appeler par son prénom = +60% confiance.
A17: Règle du Pilote | B17: 🎁 | C17: 30 jours gratuits sans engagement. Relance J+15 et J+30. Ne pas attendre son retour.
A20: GUIDE TERRAIN — APPROCHER UNE DIRECTRICE
A21: Meilleur horaire | B21: 🕘 | C21: 8h30–10h30 ou 14h–16h. Jamais à l'accueil (7h–8h) ou sortie (17h–18h).
A22: Ce qu'il faut | B22: 💼 | C22: Tablette chargée + flyer A5 couleur + carte de visite. Data de secours.
A23: Accroche ouverture | B23: 💬 | C23: 'J'ai quelque chose à montrer aux enfants qu'ils adorent — 5 minutes?' Pas de pitch direct.
A24: La démo gagnante | B24: 🎨 | C24: Laisser LA DIRECTRICE colorier elle-même l'éléphant. Elle doit vivre l'expérience.
A25: Avant de partir | B25: 📋 | C25: 'Puis-je vous envoyer un accès gratuit 30j par WhatsApp ce soir?' — Récupérer son numéro.
